<?xml version="1.0"?>
<robot name="mira">

    <!--colors-->
    <material name="green">
        <color rgba="0 0.8 0 1"/>
    </material>

    <material name="blue">
        <color rgba="0 0 0.8 1"/>
    </material>

    <material name="yellow">
        <color rgba="240 255 0 1"/>
    </material>

    <material name="black">
        <color rgba="0 0 0 1"/>
    </material>

    <material name="white">
        <color rgba="1 1 1 1"/>
    </material>



    <!--links-->
    <link name="base_link">
        <collision>
            <origin xyz="0 0 0" rpy="0 0 0"/>
            <geometry>
                <cylinder radius="0.06" length="0.09">
            <geometry/>
        </collision>
        <visual>
        <origin rpy="0 0 0" xyz="0 0 0"/>
        <geometry>
            <mesh filename="package://my_mira_description/models/meshes/mira_body_v3.dae"/>
        </geometry>
        </visual>
    </link>
    <link name="roll_M1_link">
        <visual>
            <origin rpy="0 0 0 " xyz="0 0 0"/> 
            <geometry>
                <cylinder radius="0.005" length="0.001"/> 
            </geometry>
            <material name="yellow"/>
        </visual>
    </link>
    <link name="pitch_M2_link">
        <visual>
            <origin rpy="0 0 0" xyz="0 0 0"/> 
            <geometry>
                <cylinder radius="0.005" length="0.001"/> 
            </geometry>
            <material name="blue"/>
        </visual>
    </link>
    <link name="yaw_M3_link">
        <visual>
            <origin rpy="0 0 0" xyz="0 0 0"/> 
            <geometry>
                <cylinder radius="0.005" length="0.001"/> 
            </geometry>
        </visual>
    </link>
    <link name="head_link">
        <visual>
            <origin rpy="0 0 0" xyz="0 0 0"/> 
            <geometry>
                <mesh filename="package://my_mira_description/models/meshes/mira_head_v5.dae"/> 
            </geometry>
        </visual>
    </link>
    <link name="left_eye_link">
        <visual>
            <origin rpy="0 0 0" xyz="0 0 0"/> 
            <geometry>
                 <mesh filename="package://my_mira_description/models/meshes/mira_eye_v4.dae"/>
            </geometry>
        </visual>
    </link>
    <link name="right_eye_link">
        <visual>
            <origin rpy="0 0 0" xyz="0 0 0"/> 
            <geometry>
                <mesh filename="package://my_mira_description/models/meshes/mira_eye_v4.dae"/>
            </geometry>
        </visual>
    </link>
    <link name="camera_link">
        <visual>
            <origin rpy="0 0 0" xyz="0 0 0"/> 
            <geometry>
                <box size ="0.0005 0.0005 0.0005"/> 
            </geometry>
            <material name="white"/>
        </visual>
    </link>
    
    











    <!--joints-->
    <joint name="roll_joint" type="revolute">
        <parent link="base_link"/>
        <child link="roll_M1_link"/>
        <origin xyz="0.0023 0 -0.0005" rpy="0 0 0"/>
        <limit lower="-0.22" upper="0.22" effort="0.1" velocity="0.005"/>
        <axis xyz="1 0 0"/>
    </joint>
    <joint name="roll_pitch_joint" type="revolute">
        <parent link="roll_M1_link"/>
        <child link="pitch_M2_link"/>
        <origin xyz="0 0 0" rpy="0 -1.5708 0"/>
        <limit lower="0" upper="0.44" effort="0.1" velocity="0.005"/>
        <axis xyz="0 1 0"/>
    </joint>
    <joint name="yaw_pitch_joint" type="revolute">
        <parent link="pitch_M2_link"/>
        <child link="yaw_M3_link"/>
        <origin xyz="0.005 0 0" rpy="0 1.5708 0"/>
        <limit lower="-1.5707" upper="1.5707" effort="0.1" velocity="0.005"/>
        <axis xyz="0 0 1"/>
    </joint>
    <joint name="yaw_head_joint" type="fixed">
        <parent link="yaw_M3_link"/>
        <child link="head_link"/>
        <origin xyz="0 0 0" rpy="0 0 0"/>
    </joint>
    
    <joint name="left_head_joint" type="fixed">
        <parent link="head_link"/>
        <child link="left_eye_link"/>
        <origin xyz="0.0095 0.057 0.0085" rpy="-1.5708 0 0"/>
    </joint>
    <joint name="right_head_joint" type="fixed">
        <parent link="head_link"/>
        <child link="right_eye_link"/>
        <origin xyz="-0.0095 0.057 0.0085" rpy="-1.5708 0 0"/>
    </joint>
    <joint name="camera_head_joint" type="fixed">
        <parent link="head_link"/>
        <child link="camera_link"/>
        <origin xyz="0 0.057 0.0255" rpy="0 0 0"/>
    </joint>
</robot>
