<?xml version="1.0"?>

<!--links definitions-->
<robot name="gurdy">
    <link name="base_link">
        <visual>
            <origin xyz="0.0 0.0 0.0" rpy="0.0 0.0 0.0"/>
            <geometry>
                <box size="0.01 0.01 0.01"/>
            </geometry>
        </visual>
    </link>
    <link name="head_link">
        <visual>
            <origin xyz="0.0 0.0 0.0" rpy="0.0 0.0 0.0"/>
            <geometry>
                <mesh filename="package://my_gurdy_description/models/meshes/gurdy_head_v2.dae"/>
            </geometry>
        </visual>
        <collision>
            <origin xyz="0.0 0.0 0.0" rpy="0.0 0.0 0.0"/>
            <geometry>
               <cylinder radius="0.05" length="0.04"/>
            </geometry>
        </collision>
    </link>
    <link name="upperleg_M1_link">_
        <visual>
            <origin xyz="0.0 0.0 0.0" rpy="0.0 0.0 0.0"/>
            <geometry>
                <mesh filename="package://my_gurdy_description/models/meshes/gurdy_higherleg_v2.dae"/>
            </geometry>
        </visual>
        <collision>
            <origin xyz="0.0 0.0 0.0" rpy="0.0 0.0 0.0"/>
            <geometry>
                <cylinder radius="0.0" length="0.0"/>
            </geometry>
        </collision>
    </link>
    <link name="upperleg_M2_link">_
        <visual>
            <origin xyz="0.0 0.0 0.0" rpy="0.0 0.0 0.0"/>
            <geometry>
                <mesh filename="package://my_gurdy_description/models/meshes/gurdy_higherleg_v2.dae"/>
            </geometry>
        </visual>
    </link>
    <link name="upperleg_M3_link">_
        <visual>
            <origin xyz="0.0 0.0 0.0" rpy="0.0 0.0 0.0"/>
            <geometry>
                <mesh filename="package://my_gurdy_description/models/meshes/gurdy_higherleg_v2.dae"/>
            </geometry>
        </visual>
    </link>
    <link name="lowerleg_M1_link">
        <visual>
            <origin xyz="0.0 0.0 0.0" rpy="0.0 0.0 0.0"/>
            <geometry>
                <mesh filename="package://my_gurdy_description/models/meshes/gurdy_lowerleg_v2.dae"/>
            </geometry>
        </visual>
    </link>
    <link name="lowerleg_M2_link">
        <visual>
            <origin xyz="0.0 0.0 0.0" rpy="0.0 0.0 0.0"/>
            <geometry>
                <mesh filename="package://my_gurdy_description/models/meshes/gurdy_lowerleg_v2.dae"/>
            </geometry>
        </visual>
    </link>
    <link name="lowerleg_M3_link">
        <visual>
            <origin xyz="0.0 0.0 0.0" rpy="0.0 0.0 0.0"/>
            <geometry>
                <mesh filename="package://my_gurdy_description/models/meshes/gurdy_lowerleg_v2.dae"/>
            </geometry>
        </visual>
    </link>
    <link name="footM1_link">
        <visual>
            <origin xyz="0.0 0.0 0.0" rpy="0.0 0.0 0.0"/>
            <geometry>
                <sphere radius="0.006"/>
            </geometry>
            <material name="red">
                <color rgba="1.0 0.0 0.0 1.0"/>
            </material>
        </visual>
    </link>
    <link name="footM2_link">
        <visual>
            <origin xyz="0.0 0.0 0.0" rpy="0.0 0.0 0.0"/>
            <geometry>
                <sphere radius="0.006"/>
            </geometry>
            <material name="blue">
                <color rgba="0.0 0.0 1.0 1.0"/>
            </material>
        </visual>
    </link>
    <link name="footM3_link">
        <visual>
            <origin xyz="0.0 0.0 0.0" rpy="0.0 0.0 0.0"/>
            <geometry>
                <sphere radius="0.006"/>
            </geometry>
            <material name="yellow">
                <color rgba="240 255 0 1"/>
            </material>
        </visual>
    </link>

    <!--joints-->
    <joint name="base_joint" type="fixed">
        <origin xyz="0.0 0.0 0.0" rpy="0.0 0.0 0.0"/>
        <parent link="base_link"/>
        <child link="head_link"/>
        <origin xyz="0.0 0.0 0.0"/>
    </joint>
    <joint name="head_upperlegM1_joint" type="revolute">
        <origin xyz="-0.02165 -0.0125 -0.008" rpy="3.14159 0 0.523599"/>
        <parent link="head_link"/>
        <child link="upperleg_M1_link"/>
        <axis xyz="0.0 1.0 0.0"/>
        <limit lower="-1.5707" upper="0.0" effort="0.0" velocity="0.005"/>
    </joint>
    <joint name="head_upperlegM2_joint" type="revolute">
        <origin xyz="0.02165 -0.0125 -0.008" rpy="3.14159 0 2.61799"/>
        <parent link="head_link"/>
        <child link="upperleg_M2_link"/>
        <axis xyz="0.0 1.0 0.0"/>
        <limit lower="-1.5707" upper="0.0" effort="0.0" velocity="0.005"/>
    </joint>
    <joint name="head_upperlegM3_joint" type="revolute">
        <origin xyz="0 0.025 -0.008" rpy="3.14159 0 -1.5708"/>
        <parent link="head_link"/>
        <child link="upperleg_M3_link"/>
        <axis xyz="0.0 1.0 0.0"/>
        <limit lower="-1.5707" upper="0.0" effort="0.0" velocity="0.005"/>
    </joint>
    <joint name="upperlegM1_lowerlegM1_joint" type="revolute">
        <origin xyz="0 0.0095 0.06" rpy="0.0 0.0 3.14159"/>
        <parent link="upperleg_M1_link"/>
        <child link="lowerleg_M1_link"/>
        <axis xyz="0.0 1.0 0.0"/>
        <limit lower="-3" upper="1.5707" effort="0.0" velocity="0.005"/>
    </joint>
    <joint name="upperlegM2_lowerlegM2_joint" type="revolute">
        <origin xyz="0 0.0095 0.06" rpy="0.0 0.0 3.14159"/>
        <parent link="upperleg_M2_link"/>
        <child link="lowerleg_M2_link"/>
        <axis xyz="0.0 1.0 0.0"/>
        <limit lower="-3" upper="1.5707" effort="0.0" velocity="0.005"/>
    </joint>
    <joint name="upperlegM3_lowerlegM3_joint" type="revolute">
        <origin xyz="0 0.0095 0.06" rpy="0.0 0.0 3.14159"/>
        <parent link="upperleg_M3_link"/>
        <child link="lowerleg_M3_link"/>
        <axis xyz="0.0 1.0 0.0"/>
        <limit lower="-3" upper="1.5707" effort="0.0" velocity="0.005"/>
    </joint>
    <joint name="lowerlegM1_footM1_link" type="fixed">
        <origin xyz="0.0 0.0 0.06" rpy="0.0 0.0 0.0"/>
        <parent link="lowerleg_M1_link"/>
        <child link="footM1_link"/>
    </joint>
     <joint name="lowerlegM2_footM2_link" type="fixed">
        <origin xyz="0.0 0.0 0.06" rpy="0.0 0.0 0.0"/>
        <parent link="lowerleg_M2_link"/>
        <child link="footM2_link"/>
    </joint>
     <joint name="lowerlegM3_footM3_link" type="fixed">
        <origin xyz="0.0 0.0 0.06" rpy="0.0 0.0 0.0"/>
        <parent link="lowerleg_M3_link"/>
        <child link="footM3_link"/>
    </joint>


</robot>
