<?xml version="1.0"?>




<robot name="gurdy">

<!--This activates the gazebo control plugin for the gurdy namespace. This namespace will be set in the main spawn launch file.-->
    <gazebo>
        <plugin name="gazebo_ros_control" filename="libgazebo_ros_control.so">
            <robotNamespace>/gurdy</robotNamespace>
        </plugin>
    </gazebo>

<!--links definitions-->
    <link name="base_link">
        <visual>
            <origin xyz="0.0 0.0 0.0" rpy="0.0 0.0 0.0"/>
            <geometry>
                <box size="0.01 0.01 0.01"/>
            </geometry>
        </visual>
        <collision>
            <origin xyz="0.0 0.0 0.0" rpy="0.0 0.0 0.0"/>
            <geometry>
                <box size="0.01 0.01 0.01"/>
            </geometry>
        </collision>
        <inertial>
            <origin xyz="0.0 0.0 0.0" rpy="0.0 0.0 0.0"/>
            <mass value="0.0"/>
            <inertia ixx="0.0" ixy="0.0" ixz="0.0" iyy="0.0" iyz="0.0" izz="0.0"/>
        </inertial>
        
    </link>
    <link name="head_link">
        <visual>
            <origin xyz="0.0 0.0 0.0" rpy="0.0 0.0 0.0"/>
            <geometry>
                <mesh filename="package://my_gurdy_description/models/meshes/gurdy_head_v2.dae"/>
            </geometry>
        </visual>
        <collision>
            <origin xyz="0.0 0.0 0.0" rpy="0.0 0.0 0.0"/>
            <geometry>
               <cylinder radius="0.05" length="0.04"/>
            </geometry>
        </collision>
        <inertial>
            <origin xyz="0.0 0.0 0.0" rpy="0.0 0.0 0.0"/>
            <mass value="0.01"/>
            <inertia ixx="7.58333e-06" ixy="0.0" ixz="0.0" iyy="7.58333e-06" iyz="0.0" izz="1.25e-05"/>
        </inertial>
    </link>
    <link name="upperleg_M1_link">_
        <visual>
            <origin xyz="0.0 0.0 0.0" rpy="0.0 0.0 0.0"/>
            <geometry>
                <mesh filename="package://my_gurdy_description/models/meshes/gurdy_higherleg_v2.dae"/>
            </geometry>
        </visual>
        <collision>
            <origin xyz="0.0 0.0 0.0" rpy="0.0 0.0 0.0"/>
            <geometry>
                <cylinder radius="0.0025" length="0.06"/>
            </geometry>
        </collision>
        <inertial>
            <origin xyz="0.0 0.0 0.0" rpy="0.0 0.0 0.0"/>
            <mass value="0.01"/>
            <inertia ixx="3.015625e-6" ixy="0.0" ixz="0.0" iyy="3.015625e-6" iyz="0.0" izz="3.125e-8"/>
        </inertial>
        
    </link>
    <link name="upperleg_M2_link">_
        <visual>
            <origin xyz="0.0 0.0 0.0" rpy="0.0 0.0 0.0"/>
            <geometry>
                <mesh filename="package://my_gurdy_description/models/meshes/gurdy_higherleg_v2.dae"/>
            </geometry>
        </visual>
        <collision>
            <origin xyz="0.0 0.0 0.0" rpy="0.0 0.0 0.0"/>
            <geometry>
                <cylinder radius="0.0025" length="0.06"/>
            </geometry>
        </collision>
        <inertial>
            <origin xyz="0.0 0.0 0.0" rpy="0.0 0.0 0.0"/>
            <mass value="0.01"/>
            <inertia ixx="3.015625e-6" ixy="0.0" ixz="0.0" iyy="3.015625e-6" iyz="0.0" izz="3.125e-8"/>
        </inertial>
    </link>
    <link name="upperleg_M3_link">_
        <visual>
            <origin xyz="0.0 0.0 0.0" rpy="0.0 0.0 0.0"/>
            <geometry>
                <mesh filename="package://my_gurdy_description/models/meshes/gurdy_higherleg_v2.dae"/>
            </geometry>
        </visual>
        <collision>
            <origin xyz="0.0 0.0 0.0" rpy="0.0 0.0 0.0"/>
            <geometry>
                <cylinder radius="0.0025" length="0.06"/>
            </geometry>
        </collision>
        <inertial>
            <origin xyz="0.0 0.0 0.0" rpy="0.0 0.0 0.0"/>
            <mass value="0.01"/>
            <inertia ixx="3.015625e-6" ixy="0.0" ixz="0.0" iyy="3.015625e-6" iyz="0.0" izz="3.125e-8"/>
        </inertial>
    </link>
    <link name="lowerleg_M1_link">
        <visual>
            <origin xyz="0.0 0.0 0.0" rpy="0.0 0.0 0.0"/>
            <geometry>
                <mesh filename="package://my_gurdy_description/models/meshes/gurdy_lowerleg_v2.dae"/>
            </geometry>
        </visual>
        <collision>
            <origin xyz="0.0 0.0 0.0" rpy="0.0 0.0 0.0"/>
            <geometry>
                <cylinder radius="0.0025" length="0.06"/>
            </geometry>
        </collision>
        <inertial>
            <origin xyz="0.0 0.0 0.0" rpy="0.0 0.0 0.0"/>
            <mass value="0.01"/>
            <inertia ixx="9.001875e-06" ixy="0.0" ixz="0.0" iyy="9.001874e-06" iyz="0.0" izz="1.8e-05"/>
        </inertial>
    </link>
    <link name="lowerleg_M2_link">
        <visual>
            <origin xyz="0.0 0.0 0.0" rpy="0.0 0.0 0.0"/>
            <geometry>
                <mesh filename="package://my_gurdy_description/models/meshes/gurdy_lowerleg_v2.dae"/>
            </geometry>
        </visual>
        <collision>
            <origin xyz="0.0 0.0 0.0" rpy="0.0 0.0 0.0"/>
            <geometry>
                <cylinder radius="0.0025" length="0.06"/>
            </geometry>
        </collision>
        <inertial>
            <origin xyz="0.0 0.0 0.0" rpy="0.0 0.0 0.0"/>
            <mass value="0.01"/>
            <inertia ixx="9.001875e-06" ixy="0.0" ixz="0.0" iyy="9.001874e-06" iyz="0.0" izz="1.8e-05"/>
        </inertial>
    </link>
    <link name="lowerleg_M3_link">
        <visual>
            <origin xyz="0.0 0.0 0.0" rpy="0.0 0.0 0.0"/>
            <geometry>
                <mesh filename="package://my_gurdy_description/models/meshes/gurdy_lowerleg_v2.dae"/>
            </geometry>
        </visual>
        <collision>
            <origin xyz="0.0 0.0 0.0" rpy="0.0 0.0 0.0"/>
            <geometry>
                <cylinder radius="0.0025" length="0.06"/>
            </geometry>
        </collision>
        <inertial>
            <origin xyz="0.0 0.0 0.0" rpy="0.0 0.0 0.0"/>
            <mass value="0.01"/>
            <inertia ixx="9.001875e-06" ixy="0.0" ixz="0.0" iyy="9.001874e-06" iyz="0.0" izz="1.8e-05"/>
        </inertial>
    </link>
    <link name="footM1_link">
        <visual>
            <origin xyz="0.0 0.0 0.0" rpy="0.0 0.0 0.0"/>
            <geometry>
                <sphere radius="0.006"/>
            </geometry>
            <material name="red">
                <color rgba="1.0 0.0 0.0 1.0"/>
            </material>
        </visual>
        <collision>
            <origin xyz="0.0 0.0 0.0" rpy="0.0 0.0 0.0"/>
            <geometry>
                <sphere radius="0.006"/>
            </geometry>
        </collision>
        <inertial>
            <origin xyz="0.0 0.0 0.0" rpy="0.0 0.0 0.0"/>
            <mass value="0.01"/>
            <inertia ixx="2.56e-07" ixy="0.0" ixz="0.0" iyy="2.56e-07" iyz="0.0" izz="2.56e-07"/>
        </inertial>
        
    </link>
    <link name="footM2_link">
        <visual>
            <origin xyz="0.0 0.0 0.0" rpy="0.0 0.0 0.0"/>
            <geometry>
                <sphere radius="0.006"/>
            </geometry>
            <material name="blue">
                <color rgba="0.0 0.0 1.0 1.0"/>
            </material>
        </visual>
        <collision>
            <origin xyz="0.0 0.0 0.0" rpy="0.0 0.0 0.0"/>
            <geometry>
                <sphere radius="0.006"/>
            </geometry>
        </collision>
        <inertial>
            <origin xyz="0.0 0.0 0.0" rpy="0.0 0.0 0.0"/>
            <mass value="0.01"/>
            <inertia ixx="2.56e-07" ixy="0.0" ixz="0.0" iyy="2.56e-07" iyz="0.0" izz="2.56e-07"/>
        </inertial>
    </link>
    <link name="footM3_link">
        <visual>
            <origin xyz="0.0 0.0 0.0" rpy="0.0 0.0 0.0"/>
            <geometry>
                <sphere radius="0.006"/>
            </geometry>
            <material name="yellow">
                <color rgba="240 255 0 1"/>
            </material>
        </visual>
        <collision>
            <origin xyz="0.0 0.0 0.0" rpy="0.0 0.0 0.0"/>
            <geometry>
                <sphere radius="0.006"/>
            </geometry>
        </collision>
        <inertial>
            <origin xyz="0.0 0.0 0.0" rpy="0.0 0.0 0.0"/>
            <mass value="0.01"/>
            <inertia ixx="2.56e-07" ixy="0.0" ixz="0.0" iyy="2.56e-07" iyz="0.0" izz="2.56e-07"/>
        </inertial>
    </link>
<!--joints-->
    <joint name="base_joint" type="fixed">
        <origin xyz="0.0 0.0 0.0" rpy="0.0 0.0 0.0"/>
        <parent link="base_link"/>
        <child link="head_link"/>
        <origin xyz="0.0 0.0 0.0"/>
    </joint>
    <joint name="head_upperlegM1_joint" type="revolute">
        <origin xyz="-0.02165 -0.0125 -0.008" rpy="3.14159 0 0.523599"/>
        <parent link="head_link"/>
        <child link="upperleg_M1_link"/>
        <axis xyz="0.0 1.0 0.0"/>
        <limit lower="-1.5707" upper="0.0" effort="1.0" velocity="0.005"/>
    </joint>
    <joint name="head_upperlegM2_joint" type="revolute">
        <origin xyz="0.02165 -0.0125 -0.008" rpy="3.14159 0 2.61799"/>
        <parent link="head_link"/>
        <child link="upperleg_M2_link"/>
        <axis xyz="0.0 1.0 0.0"/>
        <limit lower="-1.5707" upper="0.0" effort="1.0" velocity="0.005"/>
    </joint>
    <joint name="head_upperlegM3_joint" type="revolute">
        <origin xyz="0 0.025 -0.008" rpy="3.14159 0 -1.5708"/>
        <parent link="head_link"/>
        <child link="upperleg_M3_link"/>
        <axis xyz="0.0 1.0 0.0"/>
        <limit lower="-1.5707" upper="0.0" effort="1.0" velocity="0.005"/>
    </joint>
    <joint name="upperlegM1_lowerlegM1_joint" type="revolute">
        <origin xyz="0 0.0095 0.06" rpy="0.0 0.0 3.14159"/>
        <parent link="upperleg_M1_link"/>
        <child link="lowerleg_M1_link"/>
        <axis xyz="0.0 1.0 0.0"/>
        <limit lower="-3" upper="1.5707" effort="1.0" velocity="0.005"/>
    </joint>
    <joint name="upperlegM2_lowerlegM2_joint" type="revolute">
        <origin xyz="0 0.0095 0.06" rpy="0.0 0.0 3.14159"/>
        <parent link="upperleg_M2_link"/>
        <child link="lowerleg_M2_link"/>
        <axis xyz="0.0 1.0 0.0"/>
        <limit lower="-3" upper="1.5707" effort="1.0" velocity="0.005"/>
    </joint>
    <joint name="upperlegM3_lowerlegM3_joint" type="revolute">
        <origin xyz="0 0.0095 0.06" rpy="0.0 0.0 3.14159"/>
        <parent link="upperleg_M3_link"/>
        <child link="lowerleg_M3_link"/>
        <axis xyz="0.0 1.0 0.0"/>
        <limit lower="-3" upper="1.5707" effort="1.0" velocity="0.005"/>
    </joint>
    <joint name="lowerlegM1_footM1_link" type="fixed">
        <origin xyz="0.0 0.0 0.06" rpy="0.0 0.0 0.0"/>
        <parent link="lowerleg_M1_link"/>
        <child link="footM1_link"/>
    </joint>
    <joint name="lowerlegM2_footM2_link" type="fixed">
        <origin xyz="0.0 0.0 0.06" rpy="0.0 0.0 0.0"/>
        <parent link="lowerleg_M2_link"/>
        <child link="footM2_link"/>
    </joint>
    <joint name="lowerlegM3_footM3_link" type="fixed">
        <origin xyz="0.0 0.0 0.06" rpy="0.0 0.0 0.0"/>
        <parent link="lowerleg_M3_link"/>
        <child link="footM3_link"/>
    </joint>

<!--joints frictions-->
    <gazebo reference="head_upperlegM1_joint">
        <kp>1000.0</kp>
        <kd>10.0</kd>
        <mu1>10.0</mu1>
        <mu2>10.0</mu2>
    </gazebo>
    <gazebo reference="head_upperlegM2_joint">
        <kp>1000.0</kp>
        <kd>10.0</kd>
        <mu1>10.0</mu1>
        <mu2>10.0</mu2>
    </gazebo>
    <gazebo reference="head_upperlegM3_joint">
        <kp>1000.0</kp>
        <kd>10.0</kd>
        <mu1>10.0</mu1>
        <mu2>10.0</mu2>
    </gazebo>
    <gazebo reference="upperlegM1_lowerlegM1_joint">
        <kp>1000.0</kp>
        <kd>10.0</kd>
        <mu1>10.0</mu1>
        <mu2>10.0</mu2>
    </gazebo>
    <gazebo reference="upperlegM1_lowerlegM2_joint">
        <kp>1000.0</kp>
        <kd>10.0</kd>
        <mu1>10.0</mu1>
        <mu2>10.0</mu2>
    </gazebo>
    <gazebo reference="upperlegM1_lowerlegM3_joint">
        <kp>1000.0</kp>
        <kd>10.0</kd>
        <mu1>10.0</mu1>
        <mu2>10.0</mu2>
    </gazebo>
    <gazebo reference="lowerlegM1_footM1_link">
        <kp>1000.0</kp>
        <kd>10.0</kd>
        <mu1>10.0</mu1>
        <mu2>10.0</mu2>
    </gazebo>
    <gazebo reference="lowerlegM2_footM2_link">
        <kp>1000.0</kp>
        <kd>10.0</kd>
        <mu1>10.0</mu1>
        <mu2>10.0</mu2>
    </gazebo>
    <gazebo reference="lowerlegM3_footM3_link">
        <kp>1000.0</kp>
        <kd>10.0</kd>
        <mu1>10.0</mu1>
        <mu2>10.0</mu2>
    </gazebo>
<!--transmissions-->
    <transmission name="transmission_head_upperlegM1_joint">
        <type>transmission_interface/SimpleTransmission</type>
        <joint name="head_upperlegM1_joint">
            <hardwareInterface>EffortJointInterface</hardwareInterface>
        </joint>
        <actuator name="motor_head_upperlegM1_joint">
            <hardwareInterface>EffortJointInterface</hardwareInterface>
            <mechanicalReduction>1</mechanicalReduction>
        </actuator>
    </transmission>
    <transmission name="transmission_head_upperlegM2_joint">
        <type>transmission_interface/SimpleTransmission</type>
        <joint name="head_upperlegM2_joint">
            <hardwareInterface>EffortJointInterface</hardwareInterface>
        </joint>
        <actuator name="motor_head_upperlegM2_joint">
            <hardwareInterface>EffortJointInterface</hardwareInterface>
            <mechanicalReduction>1</mechanicalReduction>
        </actuator>
    </transmission>
    <transmission name="transmission_head_upperlegM3_joint">
        <type>transmission_interface/SimpleTransmission</type>
        <joint name="head_upperlegM3_joint">
            <hardwareInterface>EffortJointInterface</hardwareInterface>
        </joint>
        <actuator name="motor_head_upperlegM3_joint">
            <hardwareInterface>EffortJointInterface</hardwareInterface>
            <mechanicalReduction>1</mechanicalReduction>
        </actuator>
    </transmission>
    <transmission name="transmission_upperlegM1_lowerlegM1_joint">
        <type>transmission_interface/SimpleTransmission</type>
        <joint name="upperlegM1_lowerlegM1_joint">
            <hardwareInterface>EffortJointInterface</hardwareInterface>
        </joint>
        <actuator name="motor_upperlegM1_lowerlegM1_joint">
            <hardwareInterface>EffortJointInterface</hardwareInterface>
            <mechanicalReduction>1</mechanicalReduction>
        </actuator>
    </transmission>
    <transmission name="transmission_upperlegM2_lowerlegM2_joint">
        <type>transmission_interface/SimpleTransmission</type>
        <joint name="upperlegM2_lowerlegM2_joint">
            <hardwareInterface>EffortJointInterface</hardwareInterface>
        </joint>
        <actuator name="motor_upperlegM2_lowerlegM2_joint">
            <hardwareInterface>EffortJointInterface</hardwareInterface>
            <mechanicalReduction>1</mechanicalReduction>
        </actuator>
    </transmission>
    <transmission name="transmission_upperlegM3_lowerlegM3_joint">
        <type>transmission_interface/SimpleTransmission</type>
        <joint name="upperlegM3_lowerlegM3_joint">
            <hardwareInterface>EffortJointInterface</hardwareInterface>
        </joint>
        <actuator name="motor_upperlegM3_lowerlegM3_joint">
            <hardwareInterface>EffortJointInterface</hardwareInterface>
            <mechanicalReduction>1</mechanicalReduction>
        </actuator>
    </transmission>
<!--imu-->
    <gazebo>
        <plugin name="gazebo_ros_imu_controller" filename="libgazebo_ros_imu.so">
            <robotNamespace>/gurdy</robotNamespace>
            <topicName>imu/data</topicName>
            <serviceName>imu/service</serviceName>
            <bodyName>base_link</bodyName>
            <gaussianNoise>0</gaussianNoise>
            <rpyOffsets>0 0 0</rpyOffsets>
            <updateRate>10.0</updateRate>
            <alwaysOn>true</alwaysOn>
            <gaussianNoise>0</gaussianNoise>
        </plugin>
    </gazebo>
</robot>
